Workbook

Sheet Cover
A1: Intel Corporation (NASDAQ: INTC)
A3: Investment Bank-Grade Financial Model
A4: Segment-Driven, Three-Statement Linked DCF
A5: Model Date: May 7, 2026 | Forecast Horizon: FY2026E - FY2028E
A8: Company | B8: Intel Corporation (INTC)
A9: Sector | B9: Semiconductors
A10: Headquarters | B10: Santa Clara, CA, USA
A11: Fiscal Year | B11: Ends last Saturday of December (52/53-week year)
A12: Reporting Segments | B12: CCG, DCAI, Intel Foundry, All Other (Mobileye + IMS + Other)
A14: Scenario Selector | B14: Assumptions tab, Cell B2 (Base / Bull / Bear)
A15: Model Architecture | B15: 12 tabs: Cover -> Key_Summary -> Assumptions -> Growth_Drivers -> Segment_Revenue -> Segment_PL -> Consolidated_PL -> BS -> Cash_Flow -> DCF -> Sensitivity -> Ratio_Analysis
A17: Key Data Sources | B17: Intel 10-K filings (FY2022-FY2025), Q1 2026 10-Q, Q1 2026 Earnings Call (Apr 23, 2026)
A18: Assumptions Date | B18: May 7, 2026 (intc_assumptions.md)
A19: Financial Data | B19: intc_financial_data.md (extracted from SEC filings)
A21: Segment Structure Note:
A22: - Effective Q1 2025: NEX (Network & Edge) integrated into CCG and DCAI; Altera deconsolidated Sep 12, 2025 (51% sold to SLP).
A23: - FY2023-FY2025 segment data is RESTATED to current 4-segment structure per 2025 10-K Note 3.
A24: - Historical data from old structure (with NEX) is available in 2024 10-K for reference but NOT used in this model.
A25: - Mobileye remains consolidated (~77% Intel ownership). Q1 2026: $3.9B goodwill impairment at Mobileye.
A26: - Ireland SCIP (Fab 34) 49% NCI bought out April 2026 (~$14.2B). Arizona SCIP 49% NCI remains.
A29: Usage Instructions:
A30: 1. Select scenario in Assumptions tab cell B2 (Base / Bull / Bear). All tabs update automatically.
A31: 2. Edit blue-fill cells in Assumptions tab to customize forecasts.
A32: 3. Check yellow-highlighted cross-validation rows (Segment_PL, BS) — both must read 0 difference.
A33: 4. DCF tab computes implied share price. Sensitivity tab provides WACC x g matrix.
A34: 5. Key_Summary tab gives executive overview; Ratio_Analysis tab provides detailed metrics.
... A42: Model generated programmatically via Python openpyxl (build_intc_model.py).

Sheet Key_Summary
A1: Intel (INTC) - Key Summary & Executive Dashboard
A2: USD Million (except per-share data)
A3: Scenario: | B3: =Assumptions!B2 -> Base
A5: Key Performance Indicators
B6: 2023A | C6: 2024A | D6: 2025A | F6: 2026E | G6: 2027E | H6: 2028E | K6: Notes
A7: Total Revenue ($M) | B7: =Consolidated_PL!B5 -> 54228 | C7: =Consolidated_PL!C5 -> 53101 | D7: =Consolidated_PL!D5 -> 52853 | F7: =Consolidated_PL!F5 -> 54652 | G7: =Consolidated_PL!G5 -> 61801.75 | H7: =Consolidated_PL!H5 -> 67643.9
A8: YoY Growth % | C8: =Consolidated_PL!C5/Consolidated_PL!B5-1 -> -0.020782622 | D8: =Consolidated_PL!D5/Consolidated_PL!C5-1 -> -0.0046703452 | F8: =Consolidated_PL!F5/Consolidated_PL!D5-1 -> 0.034037803 | G8: =Consolidated_PL!G5/Consolidated_PL!F5-1 -> 0.13082321 | H8: =Consolidated_PL!H5/Consolidated_PL!G5-1 -> 0.094530495
A9: Gross Profit ($M) | B9: =Consolidated_PL!B7 -> 21711 | C9: =Consolidated_PL!C7 -> 17345 | D9: =Consolidated_PL!D7 -> 18375 | F9: =Consolidated_PL!F7 -> 21041.02 | G9: =Consolidated_PL!G7 -> 25338.717 | H9: =Consolidated_PL!H7 -> 29425.096
A10: Gross Margin % | B10: =Consolidated_PL!B7/Consolidated_PL!B5 -> 0.40036513 | C10: =Consolidated_PL!C7/Consolidated_PL!C5 -> 0.32664168 | D10: =Consolidated_PL!D7/Consolidated_PL!D5 -> 0.34766238 | F10: =Consolidated_PL!F7/Consolidated_PL!F5 -> 0.385 | G10: =Consolidated_PL!G7/Consolidated_PL!G5 -> 0.41 | H10: =Consolidated_PL!H7/Consolidated_PL!H5 -> 0.435
A11: EBIT ($M) | B11: =Consolidated_PL!B17 -> 298 | C11: =Consolidated_PL!C17 -> -11517 | D11: =Consolidated_PL!D17 -> -2833 | F11: =Consolidated_PL!F17 -> 2604.31 | G11: =Consolidated_PL!G17 -> 6851.3503 | H11: =Consolidated_PL!H17 -> 10636.382
A12: EBIT Margin % | B12: =Consolidated_PL!B17/Consolidated_PL!B5 -> 0.0054953161 | C12: =Consolidated_PL!C17/Consolidated_PL!C5 -> -0.21688857 | D12: =Consolidated_PL!D17/Consolidated_PL!D5 -> -0.053601498 | F12: =Consolidated_PL!F17/Consolidated_PL!F5 -> 0.047652602 | G12: =Consolidated_PL!G17/Consolidated_PL!G5 -> 0.11086013 | H12: =Consolidated_PL!H17/Consolidated_PL!H5 -> 0.15724082
A13: Net Income to Intel ($M) | B13: =Consolidated_PL!B29 -> 1894 | C13: =Consolidated_PL!C29 -> -18595 | D13: =Consolidated_PL!D29 -> -886 | F13: =Consolidated_PL!F29 -> 837.7928 | G13: =Consolidated_PL!G29 -> 4338.6747 | H13: =Consolidated_PL!H29 -> 7805.6523
A14: Net Margin % | B14: =Consolidated_PL!B29/Consolidated_PL!B5 -> 0.034926606 | C14: =Consolidated_PL!C29/Consolidated_PL!C5 -> -0.35018173 | D14: =Consolidated_PL!D29/Consolidated_PL!D5 -> -0.016763476 | F14: =Consolidated_PL!F29/Consolidated_PL!F5 -> 0.015329591 | G14: =Consolidated_PL!G29/Consolidated_PL!G5 -> 0.070203105 | H14: =Consolidated_PL!H29/Consolidated_PL!H5 -> 0.11539329
A15: Diluted EPS ($) | B15: =Consolidated_PL!B35 -> 0.44966762 | C15: =Consolidated_PL!C35 -> -4.3446262 | D15: =Consolidated_PL!D35 -> -0.19558499 | F15: =Consolidated_PL!F35 -> 0.1642731 | G15: =Consolidated_PL!G35 -> 0.83758199 | H15: =Consolidated_PL!H35 -> 1.4867909
A16: D&A ($M) | B16: =Consolidated_PL!B32 -> 7847 | C16: =Consolidated_PL!C32 -> 9951 | D16: =Consolidated_PL!D32 -> 10757 | F16: =Consolidated_PL!F32 -> 12500 | G16: =Consolidated_PL!G32 -> 13200 | H16: =Consolidated_PL!H32 -> 13800
A17: EBITDA ($M) | B17: =Consolidated_PL!B17+Consolidated_PL!B32 -> 8145 | C17: =Consolidated_PL!C17+Consolidated_PL!C32 -> -1566 | D17: =Consolidated_PL!D17+Consolidated_PL!D32 -> 7924 | F17: =Consolidated_PL!F17+Consolidated_PL!F32 -> 15104.31 | G17: =Consolidated_PL!G17+Consolidated_PL!G32 -> 20051.35 | H17: =Consolidated_PL!H17+Consolidated_PL!H32 -> 24436.382
A18: FCF ($M) | B18: =Cash_Flow!B28 -> -11248 | C18: =Cash_Flow!C28 -> -28562 | D18: =Cash_Flow!D28 -> -9155 | F18: =Cash_Flow!F28 -> -679.09679 | G18: =Cash_Flow!G28 -> 4599.9923 | H18: =Cash_Flow!H28 -> 6664.7433
A20: Revenue by Segment ($M)
A21: CCG | B21: =Segment_Revenue!B5 -> 32305 | C21: =Segment_Revenue!C5 -> 33346 | D21: =Segment_Revenue!D5 -> 32228 | F21: =Segment_Revenue!F5 -> 32760 | G21: =Segment_Revenue!G5 -> 34966.75 | H21: =Segment_Revenue!H5 -> 36266.4
A22: DCAI | B22: =Segment_Revenue!B8 -> 15980 | C22: =Segment_Revenue!C8 -> 16125 | D22: =Segment_Revenue!D8 -> 16919 | F22: =Segment_Revenue!F8 -> 17920 | G22: =Segment_Revenue!G8 -> 21755 | H22: =Segment_Revenue!H8 -> 24987.5
A23: Intel Foundry | B23: =Segment_Revenue!B11 -> 18504 | C23: =Segment_Revenue!C11 -> 17317 | D23: =Segment_Revenue!D11 -> 17826 | F23: =Segment_Revenue!F11 -> 18398.5 | G23: =Segment_Revenue!G11 -> 20109.3 | H23: =Segment_Revenue!H11 -> 22255.25
A24: All Other | B24: =Segment_Revenue!B14 -> 5463 | C24: =Segment_Revenue!C14 -> 3601 | D24: =Segment_Revenue!D14 -> 3563 | F24: =Segment_Revenue!F14 -> 3472 | G24: =Segment_Revenue!G14 -> 3780 | H24: =Segment_Revenue!H14 -> 4090
A25: Total Consolidated | B25: =Segment_Revenue!B21 -> 54228 | C25: =Segment_Revenue!C21 -> 53101 | D25: =Segment_Revenue!D21 -> 52853 | F25: =Segment_Revenue!F21 -> 54652 | G25: =Segment_Revenue!G21 -> 61801.75 | H25: =Segment_Revenue!H21 -> 67643.9
A27: Balance Sheet Highlights ($M)
A28: Total Assets | B28: =BS!B21 -> 191572 | C28: =BS!C21 -> 196485 | D28: =BS!D21 -> 211429 | F28: =BS!F21 -> 217237.96 | G28: =BS!G21 -> 226088.93 | H28: =BS!H21 -> 238761.95
A29: Total Equity | B29: =BS!B42 -> 109965 | C29: =BS!C42 -> 105032 | D29: =BS!D42 -> 126360 | F29: =BS!F42 -> 130447.79 | G29: =BS!G42 -> 138386.47 | H29: =BS!H42 -> 149792.12
A30: Cash + Securities | B30: =BS!B7+BS!B8 -> 25034 | C30: =BS!C7+BS!C8 -> 22062 | D30: =BS!D7+BS!D8 -> 37416 | F30: =BS!F7+BS!F8 -> 45388.263 | G30: =BS!G7+BS!G8 -> 45900.335 | H30: =BS!H7+BS!H8 -> 49995.591
A31: Total Debt | B31: =BS!B34+BS!B28 -> 49266 | C31: =BS!C34+BS!C28 -> 50011 | D31: =BS!D34+BS!D28 -> 46585 | F31: =BS!F34+BS!F28 -> 49500 | G31: =BS!G34+BS!G28 -> 47200 | H31: =BS!H34+BS!H28 -> 46000
A32: Net Cash / (Debt) | B32: =BS!B7+BS!B8-BS!B34-BS!B28 -> -24232 | C32: =BS!C7+BS!C8-BS!C34-BS!C28 -> -27949 | D32: =BS!D7+BS!D8-BS!D34-BS!D28 -> -9169 | F32: =BS!F7+BS!F8-BS!F34-BS!F28 -> -4111.7368 | G32: =BS!G7+BS!G8-BS!G34-BS!G28 -> -1299.6645 | H32: =BS!H7+BS!H8-BS!H34-BS!H28 -> 3995.5908
A33: ROE | B33: =Consolidated_PL!B29/BS!B40 -> 0.017937305 | C33: =Consolidated_PL!C29/BS!C40 -> -0.18731742 | D33: =Consolidated_PL!D29/BS!D40 -> -0.0077528198 | F33: =Consolidated_PL!F29/BS!F40 -> 0.0071048285 | G33: =Consolidated_PL!G29/BS!G40 -> 0.034693448 | H33: =Consolidated_PL!H29/BS!H40 -> 0.057537025
A34: ROA | B34: =Consolidated_PL!B26/BS!B21 -> 0.0098135427 | C34: =Consolidated_PL!C26/BS!C21 -> -0.097065934 | D34: =Consolidated_PL!D26/BS!D21 -> -0.002804724 | F34: =Consolidated_PL!F26/BS!F21 -> 0.0073090025 | G34: =Consolidated_PL!G26/BS!G21 -> 0.024055466 | H34: =Consolidated_PL!H26/BS!H21 -> 0.037299295
A36: DCF Valuation Output
A37: Implied Share Price ($) | H37: =DCF!H35 -> 0.17436777 | K37: Base case DCF output. See Sensitivity tab for range.
A38: Enterprise Value ($M) | H38: =DCF!H24 -> 11048.84
A39: Equity Value ($M) | H39: =DCF!H33 -> 915.43078
A41: Investment Highlights
A42: 1. CPU Renaissance: DCAI benefiting from AI inference shift toward CPUs (CPU:GPU ratio 1:8->1:1)
A43: 2. 18A Ramp: Ahead of internal yield targets; volume up 6-7x in Q2 2026 vs Q1
A44: 3. Foundry Losses Narrowing: -58% OPM (FY2025) -> -22% (FY2028E Base) as 18A matures
A45: 4. Gross Margin Recovery: 34.8% (FY2025) -> 43.5% (FY2028E Base) driven by yield + pricing
...

Sheet Assumptions
A1: Intel (INTC) — Assumptions & Scenario Design
A2: Scenario: | B2: Base
B4: 2023A | C4: 2024A | D4: 2025A | F4: 2026E | G4: 2027E | H4: 2028E | I4: Selected | K4: Notes
A6: WACC Parameters
A7: Risk-Free Rate (Rf) | B7: 0.0388 | C7: 0.0425 | D7: 0.045 | F7: 0.045 | G7: 0.045 | H7: 0.045 | I7: =CHOOSE(MATCH($B$2,{"Base","Bull","Bear"},0),F7,G7,H7) -> 0.045 | K7: US 10Y Treasury, May 2026
A8: Equity Risk Premium (ERP) | B8: 0.055 | C8: 0.055 | D8: 0.055 | F8: 0.055 | G8: 0.055 | H8: 0.055 | I8: =CHOOSE(MATCH($B$2,{"Base","Bull","Bear"},0),F8,G8,H8) -> 0.055 | K8: Damodaran 2026 implied ERP
A9: Levered Beta (β) | B9: 1.2 | C9: 1.35 | D9: 1.5 | F9: 1.5 | G9: 1.3 | H9: 1.8 | I9: =CHOOSE(MATCH($B$2,{"Base","Bull","Bear"},0),F9,G9,H9) -> 1.5 | K9: Bloomberg 2Y adj beta; Bear=1.80 on higher risk
A10: Pre-Tax Cost of Debt (Kd) | B10: 0.048 | C10: 0.05 | D10: 0.05 | F10: 0.05 | G10: 0.05 | H10: 0.05 | I10: =CHOOSE(MATCH($B$2,{"Base","Bull","Bear"},0),F10,G10,H10) -> 0.05 | K10: Weighted avg coupon on outstanding notes
A11: Target D/(D+E) | B11: 0.3 | C11: 0.32 | D11: 0.32 | F11: 0.25 | G11: 0.2 | H11: 0.35 | I11: =CHOOSE(MATCH($B$2,{"Base","Bull","Bear"},0),F11,G11,H11) -> 0.25 | K11: Long-term target; D/EV =32% at current prices
A12: Marginal Tax Rate (for WACC) | F12: 0.12 | G12: 0.11 | H12: 0.15 | I12: =CHOOSE(MATCH($B$2,{"Base","Bull","Bear"},0),F12,G12,H12) -> 0.12 | K12: Marginal rate for interest tax shield. Base=12% (aligned with Q2 2026 guided 11%)
A13: Terminal Growth Rate (g) | F13: 0.025 | G13: 0.03 | H13: 0.02 | I13: =CHOOSE(MATCH($B$2,{"Base","Bull","Bear"},0),F13,G13,H13) -> 0.025 | K13: Base=2.5% LT nominal GDP+; Bull=3.0% AI secular; Bear=2.0% mature
A15: Derived WACC
A16: Cost of Equity (Ke) | B16: =I7+I9*I8 -> 0.1275 | F16: =F7+F9*F8 -> 0.1275 | G16: =G7+G9*G8 -> 0.1165 | H16: =H7+H9*H8 -> 0.144 | I16: =CHOOSE(MATCH($B$2,{"Base","Bull","Bear"},0),F16,G16,H16) -> 0.1275 | K16: Ke = Rf + β × ERP
A17: After-Tax Cost of Debt | I17: =I10*(1-I12) -> 0.044 | K17: Kd × (1 − ETR)
A18: WACC | I18: =I16*(1-I11)+I17*I11 -> 0.106625 | K18: WACC = Ke×(1−D/TC) + Kd(1−t)×D/TC. Links to DCF tab
A20: Valuation Bridge Inputs
A21: Cash & Equivalents ($M) — from BS | K21: To be linked from BS post-build (hardcoded anchor for DCF bridge)
A22: Total Debt ($M) — from BS
A24: Revenue Growth Assumptions
A25: CCG Revenue Growth 2026E | C25: 0.032 | D25: -0.034 | F25: 0.02 | G25: 0.05 | H25: -0.03 | I25: =CHOOSE(MATCH($B$2,{"Base","Bull","Bear"},0),F25,G25,H25) -> 0.02 | K25: Supply recovery offsets PC TAM decline
A26: CCG Revenue Growth 2027E | C26: 0.032 | D26: -0.034 | F26: 0.03 | G26: 0.06 | H26: 0 | I26: =CHOOSE(MATCH($B$2,{"Base","Bull","Bear"},0),F26,G26,H26) -> 0.03 | K26: Modest PC unit growth + AI PC ASP lift
A27: CCG Revenue Growth 2028E | C27: 0.032 | D27: -0.034 | F27: 0.03 | G27: 0.05 | H27: 0.01 | I27: =CHOOSE(MATCH($B$2,{"Base","Bull","Bear"},0),F27,G27,H27) -> 0.03 | K27: Maturing AI PC cycle
A29: DCAI Revenue Growth 2026E | C29: 0.009 | D29: 0.049 | F29: 0.18 | G29: 0.25 | H29: 0.1 | I29: =CHOOSE(MATCH($B$2,{"Base","Bull","Bear"},0),F29,G29,H29) -> 0.18 | K29: Supply recovery + CPU demand + ASIC ramp
A30: DCAI Revenue Growth 2027E | C30: 0.009 | D30: 0.049 | F30: 0.12 | G30: 0.18 | H30: 0.05 | I30: =CHOOSE(MATCH($B$2,{"Base","Bull","Bear"},0),F30,G30,H30) -> 0.12 | K30: Moderates as base effect kicks in
A31: DCAI Revenue Growth 2028E | C31: 0.009 | D31: 0.049 | F31: 0.08 | G31: 0.12 | H31: 0.02 | I31: =CHOOSE(MATCH($B$2,{"Base","Bull","Bear"},0),F31,G31,H31) -> 0.08 | K31: CPU structural demand from AI inference
A33: Intel Foundry Revenue Growth 2026E | C33: -0.064 | D33: 0.029 | F33: 0.12 | G33: 0.18 | H33: 0.05 | I33: =CHOOSE(MATCH($B$2,{"Base","Bull","Bear"},0),F33,G33,H33) -> 0.12 | K33: EUV node ramp + internal product demand
A34: Intel Foundry Revenue Growth 2027E | C34: -0.064 | D34: 0.029 | F34: 0.1 | G34: 0.2 | H34: 0.03 | I34: =CHOOSE(MATCH($B$2,{"Base","Bull","Bear"},0),F34,G34,H34) -> 0.1 | K34: External customer + adv packaging ramps
A35: Intel Foundry Revenue Growth 2028E | C35: -0.064 | D35: 0.029 | F35: 0.1 | G35: 0.18 | H35: 0.03 | I35: =CHOOSE(MATCH($B$2,{"Base","Bull","Bear"},0),F35,G35,H35) -> 0.1 | K35: 14A early revenue possible
A37: All Other Revenue Growth 2026E | C37: -0.341 | D37: -0.011 | F37: -0.05 | G37: 0.05 | H37: -0.15 | I37: =CHOOSE(MATCH($B$2,{"Base","Bull","Bear"},0),F37,G37,H37) -> -0.05 | K37: Mobileye headwinds + Altera deconsolidation
A38: All Other Revenue Growth 2027E | C38: -0.341 | D38: -0.011 | F38: 0.08 | G38: 0.15 | H38: -0.05 | I38: =CHOOSE(MATCH($B$2,{"Base","Bull","Bear"},0),F38,G38,H38) -> 0.08 | K38: Mobileye recovery as SuperVision ramps
A39: All Other Revenue Growth 2028E | C39: -0.341 | D39: -0.011 | F39: 0.08 | G39: 0.12 | H39: 0.02 | I39: =CHOOSE(MATCH($B$2,{"Base","Bull","Bear"},0),F39,G39,H39) -> 0.08 | K39: Mobileye+IMS sustained growth
A42: CCG Bottom-Up Drivers: Revenue = PC TAM x Intel Share x ASP
A43: PC TAM (M units) — Source: Gartner/IDC
A44: PC TAM — FY2026E | C44: 241.8 | D44: 245.4 | F44: 260 | G44: 270 | H44: 250 | I44: =CHOOSE(MATCH($B$2,{"Base","Bull","Bear"},0),F44,G44,H44) -> 260 | K44: Gartner: 2023=241.8M, 2024=245.4M. 2025E ~259M. Base=+0.5% modest recovery
A45: PC TAM — FY2027E | F45: 265 | G45: 280 | H45: 252 | I45: =CHOOSE(MATCH($B$2,{"Base","Bull","Bear"},0),F45,G45,H45) -> 265 | K45: Windows 10 EOL refresh + AI PC adoption. Bull: strong enterprise refresh
A46: PC TAM — FY2028E | F46: 270 | G46: 290 | H46: 255 | I46: =CHOOSE(MATCH($B$2,{"Base","Bull","Bear"},0),F46,G46,H46) -> 270 | K46: AI PC matures; modest long-term growth
A48: Intel PC Unit Share (%) — Source: Mercury Research
A49: Intel Share — FY2026E | C49: 0.71 | D49: 0.715 | F49: 0.72 | G49: 0.74 | H49: 0.7 | I49: =CHOOSE(MATCH($B$2,{"Base","Bull","Bear"},0),F49,G49,H49) -> 0.72 | K49: Mercury est: Q4'24 ~72%. 18A products competitive; share recovery assumed
A50: Intel Share — FY2027E | F50: 0.725 | G50: 0.75 | H50: 0.69 | I50: =CHOOSE(MATCH($B$2,{"Base","Bull","Bear"},0),F50,G50,H50) -> 0.725 | K50: Panther Lake + Nova Lake sustain competitiveness
A51: Intel Share — FY2028E | F51: 0.73 | G51: 0.76 | H51: 0.68 | I51: =CHOOSE(MATCH($B$2,{"Base","Bull","Bear"},0),F51,G51,H51) -> 0.73 | K51: Continued share recovery with leading-edge nodes
...

Sheet Growth_Drivers
A1: Intel (INTC) - Revenue Growth Drivers
A2: USD Million (except per-share data)
B3: 2023A | C3: 2024A | D3: 2025A | F3: 2026E | G3: 2027E | H3: 2028E | K3: Notes
A4: USD Million / M Units / $ per Unit | K4: Bottom-up revenue decomposition. Data sources cited inline.
A5: CCG: Client Computing Group — Bottom-Up
A6: Method: Revenue = PC TAM (M units) × Intel Unit Share (%) × Blended ASP ($) | K6: TAM source: Gartner/IDC (2023=241.8M, 2024=245.4M). Share: Mercury Research est. ASP: derived from rev/(TAM×share).
A7: PC TAM (M units) | B7: 241.8 | C7: 245.4 | D7: 258.6 | F7: =Assumptions!I44 -> 260 | G7: =Assumptions!I45 -> 265 | H7: =Assumptions!I46 -> 270 | K7: Source: Gartner/IDC. 2025 est. based on Canalys ~259M full-year
A8: Intel PC Unit Share (%) | B8: 0.71 | C8: 0.715 | D8: 0.72 | F8: =Assumptions!I49 -> 0.72 | G8: =Assumptions!I50 -> 0.725 | H8: =Assumptions!I51 -> 0.73 | K8: Source: Mercury Research x86 PC CPU share. Q4'24 est. ~72%
A9: Intel Implied Units (M) | B9: =B7*B8 -> 171.678 | C9: =C7*C8 -> 175.461 | D9: =D7*D8 -> 186.192 | F9: =F7*F8 -> 187.2 | G9: =G7*G8 -> 192.125 | H9: =H7*H8 -> 197.1 | K9: PC TAM × Intel Share. Implied unit shipments
A10: Intel CCG Blended ASP ($) | B10: 188 | C10: 190 | D10: 173 | F10: =Assumptions!I54 -> 175 | G10: =Assumptions!I55 -> 182 | H10: =Assumptions!I56 -> 184 | K10: Historical: derived as Reported Revenue / Implied Units. Q1 2026 ASP +16% YoY
A11: Implied CCG Revenue ($M) | B11: =B9*B10 -> 32275.464 | C11: =C9*C10 -> 33337.59 | D11: =D9*D10 -> 32211.216 | F11: =F9*F10 -> 32760 | G11: =G9*G10 -> 34966.75 | H11: =H9*H10 -> 36266.4 | K11: Units × ASP. Bottom-up revenue estimate
A12: Reported CCG Revenue ($M) | B12: =Segment_Revenue!B5 -> 32305 | C12: =Segment_Revenue!C5 -> 33346 | D12: =Segment_Revenue!D5 -> 32228 | F12: =F11 -> 32760 | G12: =G11 -> 34966.75 | H12: =H11 -> 36266.4 | K12: Historical: links to Segment_Revenue (10-K). Forecast: = Implied (Segment_Revenue pulls from Growth_Drivers)
A13: Reconciliation: Implied − Reported ($M) | B13: =B11-B12 -> -29.536 | C13: =C11-C12 -> -8.41 | D13: =D11-D12 -> -16.784 | F13: =F11-F12 -> 0 | G13: =G11-G12 -> 0 | H13: =H11-H12 -> 0 | K13: Should be near-zero for historical (within 0.1%). Forecast: divergence flags assumption inconsistency
A14: Reconcil. as % of Reported | B14: =B13/B12 -> -0.00091428571 | C14: =C13/C12 -> -0.00025220416 | D14: =D13/D12 -> -0.00052078938 | F14: =F13/F12 -> 0 | G14: =G13/G12 -> 0 | H14: =H13/H12 -> 0 | K14: Green if <1%
A16: DCAI: Data Center & AI — Bottom-Up
A17: Method: Revenue = Server TAM (M) × Intel DC Share (%) × ASP ($) + AI/ASIC ($M) | K17: TAM: IDC. Share: Mercury Research. AI/ASIC: Gaudi+custom ASICs+NICs/IPUs. Q1 2026 ASIC run rate >$1B.
A18: Server TAM (M units) | B18: 11.5 | C18: 12 | D18: 13.5 | F18: =Assumptions!I60 -> 13.5 | G18: =Assumptions!I61 -> 14.5 | H18: =Assumptions!I62 -> 15.5 | K18: Source: IDC. 2023=11.5M, 2024=12.0M, 2025=13.5M. AI buildout driving unit growth
A19: Intel DC Server Unit Share (%) | B19: 0.775 | C19: 0.76 | D19: 0.73 | F19: =Assumptions!I65 -> 0.7 | G19: =Assumptions!I66 -> 0.7 | H19: =Assumptions!I67 -> 0.7 | K19: Source: Mercury Research x86 server CPU share. Q4 2024 ~72%. Granite Rapids competitive vs Turin
A20: Intel Implied DC Units (M) | B20: =B18*B19 -> 8.9125 | C20: =C18*C19 -> 9.12 | D20: =D18*D19 -> 9.855 | F20: =F18*F19 -> 9.45 | G20: =G18*G19 -> 10.15 | H20: =H18*H19 -> 10.85 | K20: Server TAM × Intel DC Share. Implied unit shipments
A21: Intel Server Blended ASP ($) | B21: 1772 | C21: 1712 | D21: 1632 | F21: =Assumptions!I70 -> 1600 | G21: =Assumptions!I71 -> 1700 | H21: =Assumptions!I72 -> 1750 | K21: Historical: derived as (DCAI Rev − AI/ASIC) / (TAM × Share). Q1 2026 ASP +27% YoY
A22: Implied CPU Revenue ($M) | B22: =B20*B21 -> 15792.95 | C22: =C20*C21 -> 15613.44 | D22: =D20*D21 -> 16083.36 | F22: =F20*F21 -> 15120 | G22: =G20*G21 -> 17255 | H22: =H20*H21 -> 18987.5 | K22: DC Units × Server ASP. Core x86 server CPU revenue
A23: AI/ASIC & Other Revenue ($M) | B23: 200 | C23: 500 | D23: 800 | F23: =Assumptions!I75 -> 2800 | G23: =Assumptions!I76 -> 4500 | H23: =Assumptions!I77 -> 6000 | K23: Gaudi AI accelerators + custom ASICs + NICs/IPUs. FY2025 ~$800M. Q1 2026 ASIC run rate >$1B
A24: Implied DCAI Revenue ($M) | B24: =B22+B23 -> 15992.95 | C24: =C22+C23 -> 16113.44 | D24: =D22+D23 -> 16883.36 | F24: =F22+F23 -> 17920 | G24: =G22+G23 -> 21755 | H24: =H22+H23 -> 24987.5 | K24: CPU Revenue + AI/ASIC Revenue. Bottom-up DCAI estimate
A25: Reported DCAI Revenue ($M) | B25: =Segment_Revenue!B8 -> 15980 | C25: =Segment_Revenue!C8 -> 16125 | D25: =Segment_Revenue!D8 -> 16919 | F25: =F24 -> 17920 | G25: =G24 -> 21755 | H25: =H24 -> 24987.5 | K25: Historical: links to Segment_Revenue (10-K). Forecast: = Implied (Segment_Revenue pulls from Growth_Drivers)
A26: Reconciliation: Implied − Reported ($M) | B26: =B24-B25 -> 12.95 | C26: =C24-C25 -> -11.56 | D26: =D24-D25 -> -35.64 | F26: =F24-F25 -> 0 | G26: =G24-G25 -> 0 | H26: =H24-H25 -> 0 | K26: Historical should be near-zero (<0.5%). Forecast: flags driver vs growth-rate assumption divergence
A27: Reconcil. as % of Reported | B27: =B26/B25 -> 0.00081038798 | C27: =C26/C25 -> -0.00071689922 | D27: =D26/D25 -> -0.0021065075 | F27: =F26/F25 -> 0 | G27: =G26/G25 -> 0 | H27: =H26/H25 -> 0 | K27: Green if <1%
A29: Intel Foundry — Bottom-Up
A30: Method: Revenue = Total Intel Chip Vol (M) × Internal Rev/Chip ($) + External Foundry ($M) | K30: ~99% internal wafer sales to Intel Products. Chip vol = CCG + DCAI units. Rev/Chip = internal transfer price.
A31: Total Intel Chip Volume (M units) | B31: =B9+B20 -> 180.5905 | C31: =C9+C20 -> 184.581 | D31: =D9+D20 -> 196.047 | F31: =F9+F20 -> 196.65 | G31: =G9+G20 -> 202.275 | H31: =H9+H20 -> 207.95 | K31: CCG Implied Units + DCAI Implied Units. Links to segment drivers above
A32: Internal Foundry Rev per Chip ($) | B32: 102.2 | C32: 93.5 | D32: 90.1 | F32: =Assumptions!I163 -> 90 | G32: =Assumptions!I164 -> 92 | H32: =Assumptions!I165 -> 95 | K32: Historical: derived as Internal Foundry Rev / Total Intel Units. Declining trend as older nodes depreciate
A33: Internal Foundry Revenue ($M) | B33: =B31*B32 -> 18456.349 | C33: =C31*C32 -> 17258.323 | D33: =D31*D32 -> 17663.835 | F33: =F31*F32 -> 17698.5 | G33: =G31*G32 -> 18609.3 | H33: =H31*H32 -> 19755.25 | K33: Total Intel Chip Vol × Internal Rev/Chip. Wafer sales to Intel CCG and DCAI divisions
A34: External Foundry Revenue ($M) | B34: 50 | C34: 60 | D34: 150 | F34: =Assumptions!I184 -> 700 | G34: =Assumptions!I185 -> 1500 | H34: =Assumptions!I186 -> 2500 | K34: 3rd-party wafer customers. FY2025 ~$150M. Growing as 18A/14A external PDK ramps
A35: Implied Total Foundry Revenue ($M) | B35: =B33+B34 -> 18506.349 | C35: =C33+C34 -> 17318.323 | D35: =D33+D34 -> 17813.835 | F35: =F33+F34 -> 18398.5 | G35: =G33+G34 -> 20109.3 | H35: =H33+H34 -> 22255.25 | K35: Internal Foundry Rev + External Foundry Rev
A36: Reported Foundry Revenue ($M) | B36: =Segment_Revenue!B11 -> 18504 | C36: =Segment_Revenue!C11 -> 17317 | D36: =Segment_Revenue!D11 -> 17826 | F36: =F35 -> 18398.5 | G36: =G35 -> 20109.3 | H36: =H35 -> 22255.25 | K36: Historical: links to Segment_Revenue (10-K). Forecast: = Implied (Segment_Revenue pulls from Growth_Drivers)
A37: Reconciliation: Implied − Reported ($M) | B37: =B35-B36 -> 2.3491 | C37: =C35-C36 -> 1.3235 | D37: =D35-D36 -> -12.1653 | F37: =F35-F36 -> 0 | G37: =G35-G36 -> 0 | H37: =H35-H36 -> 0 | K37: Historical should be near-zero (<0.1%). Forecast: flags driver vs growth-rate assumption divergence
A38: Reconcil. as % of Reported | B38: =B37/B36 -> 0.00012695093 | C38: =C37/C36 -> 7.6427788e-05 | D38: =D37/D36 -> -0.00068244699 | F38: =F37/F36 -> 0 | G38: =G37/G36 -> 0 | H38: =H37/H36 -> 0 | K38: Green if <1%
A40: All Other: Mobileye + IMS + Legacy — Bottom-Up
A41: Method: Revenue = LV Production (M) × Mobileye Rev/Vehicle ($) + IMS & Other ($M) | K41: All Other = Mobileye (ADAS chips) + IMS (nanofab tools) + legacy. LV Prod source: IHS/S&P Global Mobility.
A42: Global Light Vehicle Production (M) | B42: 89 | C42: 88 | D42: 87 | F42: =Assumptions!I169 -> 88 | G42: =Assumptions!I170 -> 89 | H42: =Assumptions!I171 -> 90 | K42: Source: IHS/S&P Global Mobility. FY2023 89M, FY2024 88M, FY2025 ~87M
A43: Mobileye Rev per Vehicle ($) | B43: 23.4 | C43: 18.9 | D43: 21.8 | F43: =Assumptions!I174 -> 19 | G43: =Assumptions!I175 -> 20 | H43: =Assumptions!I176 -> 21 | K43: Historical: FY2023 $23.4 (pre-destock), FY2024 $18.9 (inventory correction), FY2025 $21.8 (recovery). Source: Intel 10-K Mobileye revenue $1.9B FY2025
...

Sheet Segment_Revenue
A1: Intel (INTC) — Segment Revenue
A2: USD Million (except per-share data)
B3: 2023A | C3: 2024A | D3: 2025A | F3: 2026E | G3: 2027E | H3: 2028E | K3: Notes
A4: USD Million | K4: Historical from 10-K Note 3; Forecast = Prior x (1 + growth)
A5: CCG - Client Computing Group | B5: 32305 | C5: 33346 | D5: 32228 | F5: =Growth_Drivers!F11 -> 32760 | G5: =Growth_Drivers!G11 -> 34966.75 | H5: =Growth_Drivers!H11 -> 36266.4 | K5: Forecast: Links to Growth_Drivers bottom-up implied revenue (pass 2)
C6: =(C5-B5)/B5 -> 0.032224114 | D6: =(D5-C5)/C5 -> -0.03352726 | F6: =F5/B5-1 -> 0.014084507 | G6: =G5/F5-1 -> 0.067361111 | H6: =H5/G5-1 -> 0.037168167 | K6: YoY Growth %
A8: DCAI - Data Center & AI | B8: 15980 | C8: 16125 | D8: 16919 | F8: =Growth_Drivers!F24 -> 17920 | G8: =Growth_Drivers!G24 -> 21755 | H8: =Growth_Drivers!H24 -> 24987.5 | K8: Forecast: Links to Growth_Drivers bottom-up implied revenue (pass 2)
C9: =(C8-B8)/B8 -> 0.0090738423 | D9: =(D8-C8)/C8 -> 0.04924031 | F9: =F8/B8-1 -> 0.12140175 | G9: =G8/F8-1 -> 0.2140067 | H9: =H8/G8-1 -> 0.14858653 | K9: YoY Growth %
A11: Intel Foundry | B11: 18504 | C11: 17317 | D11: 17826 | F11: =Growth_Drivers!F35 -> 18398.5 | G11: =Growth_Drivers!G35 -> 20109.3 | H11: =Growth_Drivers!H35 -> 22255.25 | K11: Forecast: Links to Growth_Drivers bottom-up implied revenue (pass 2)
C12: =(C11-B11)/B11 -> -0.064148292 | D12: =(D11-C11)/C11 -> 0.029393082 | F12: =F11/B11-1 -> -0.00570147 | G12: =G11/F11-1 -> 0.092985841 | H12: =H11/G11-1 -> 0.10671431 | K12: YoY Growth %
A14: All Other (Mobileye + IMS + Other) | B14: 5463 | C14: 3601 | D14: 3563 | F14: =Growth_Drivers!F46 -> 3472 | G14: =Growth_Drivers!G46 -> 3780 | H14: =Growth_Drivers!H46 -> 4090 | K14: Forecast: Links to Growth_Drivers bottom-up implied revenue (pass 2)
C15: =(C14-B14)/B14 -> -0.34083837 | D15: =(D14-C14)/C14 -> -0.010552624 | F15: =F14/B14-1 -> -0.36445177 | G15: =G14/F14-1 -> 0.088709677 | H15: =H14/G14-1 -> 0.082010582 | K15: YoY Growth %
A17: Memo: Total Segment Revenue (incl. internal Foundry) | B17: =B5+B8+B11+B14 -> 72252 | C17: =C5+C8+C11+C14 -> 70389 | D17: =D5+D8+D11+D14 -> 70536 | F17: =F5+F8+F11+F14 -> 72550.5 | G17: =G5+G8+G11+G14 -> 80611.05 | H17: =H5+H8+H11+H14 -> 87599.15 | K17: Sum of 4 reported segments; Foundry ~99% internal → excluded from consolidated
A19: External Foundry Revenue (3rd-party only) | B19: 50 | C19: 60 | D19: 150 | F19: =Assumptions!I184 -> 700 | G19: =Assumptions!I185 -> 1500 | H19: =Assumptions!I186 -> 2500 | K19: ~1% of total Foundry revenue historically. Growing as 18A/14A external customers ramp
A20: Intersegment Eliminations | B20: -205 | C20: -161 | D20: 619 | F20: =Assumptions!I188 -> -200 | G20: =Assumptions!I188 -> -200 | H20: =Assumptions!I188 -> -200 | K20: Residual elim; Foundry~Products internal wafer sales excluded from consolidated
A21: TOTAL Consolidated Revenue | B21: 54228 | C21: 53101 | D21: 52853 | F21: =F5+F8+F14+F19+F20 -> 54652 | G21: =G5+G8+G14+G19+G20 -> 61801.75 | H21: =H5+H8+H14+H19+H20 -> 67643.9 | K21: Historical: 10-K actuals. Forecast: CCG+DCAI+ExtFoundry+AllOther+Elim. Links to Consolidated_PL
A23: CCG % | B23: =B5/B21 -> 0.59572546 | C23: =C5/C21 -> 0.62797311 | D23: =D5/D21 -> 0.60976671 | F23: =F5/F21 -> 0.59942912 | G23: =G5/G21 -> 0.56578899 | H23: =H5/H21 -> 0.53613704
A24: DCAI % | B24: =B8/B21 -> 0.29468171 | C24: =C8/C21 -> 0.3036666 | D24: =D8/D21 -> 0.32011428 | F24: =F8/F21 -> 0.32789285 | G24: =G8/G21 -> 0.35201269 | H24: =H8/H21 -> 0.36939768
A25: All Other % | B25: =B14/B21 -> 0.10074131 | C25: =C14/C21 -> 0.067814165 | D25: =D14/D21 -> 0.067413392 | F25: =F14/F21 -> 0.06352924 | G25: =G14/G21 -> 0.061163317 | H25: =H14/H21 -> 0.060463693
A26: External Foundry % | B26: =B19/B21 -> 0.0009220329 | C26: =C19/C21 -> 0.0011299222 | D26: =D19/D21 -> 0.0028380603 | F26: =F19/F21 -> 0.012808314 | G26: =G19/G21 -> 0.024271157 | H26: =H19/H21 -> 0.036958248 | K26: External foundry only; internal wafer sales eliminated
A27: Memo: Total Foundry / Seg Sum | B27: =B11/B17 -> 0.25610364 | C27: =C11/C17 -> 0.24601855 | D27: =D11/D17 -> 0.25272201 | F27: =F11/F17 -> 0.25359577 | G27: =G11/G17 -> 0.24946084 | H27: =H11/H17 -> 0.25405783 | K27: Shows Foundry scale relative to all segments
A29: DATA LEGEND
A30: Blue font: Historical hardcoded data
A31: Green font: Cross-sheet link
A32: Blue fill + dark font: Editable assumption
A33: Yellow fill: Key output row
A34: Black font: Formula / calculated cell
A35: Grey italic: Memo / percentage row
A37: DATA SOURCES
A38: - 2022-2025 10-Ks: Consolidated P&L, Balance Sheet, Cash Flow, Segment data
A39: - 2026 Q1 10-Q: Q1 2026 vs Q1 2025 segment + consolidated data
A40: - Q1 2026 Earnings Call (Apr 23, 2026): FY2026 management guidance
A41: - intc_assumptions.md: All forecast assumptions with scenario narratives
A42: - Bloomberg / Damodaran / FRED: WACC inputs (Rf, ERP, Beta) as of May 2026

Sheet Segment_PL
A1: Intel (INTC) - Segment P&L (Operating Income by Division)
A2: USD Million (except per-share data)
B3: 2023A | C3: 2024A | D3: 2025A | F3: 2026E | G3: 2027E | H3: 2028E | K3: Notes
A4: USD Million (except margin %) | K4: OI = Segment Revenue x OPM% from Assumptions. EBIT links to Consolidated_PL.
A5: CCG - Client Computing Group | B5: =Segment_Revenue!B5 -> 32305 | C5: =Segment_Revenue!C5 -> 33346 | D5: =Segment_Revenue!D5 -> 32228 | F5: =Segment_Revenue!F5 -> 32760 | G5: =Segment_Revenue!G5 -> 34966.75 | H5: =Segment_Revenue!H5 -> 36266.4 | K5: Revenue <- links Segment_Revenue
A6: Operating Income | B6: 10128 | C6: 11594 | D6: 9317 | F6: =F5*Assumptions!I79 -> 9828 | G6: =G5*Assumptions!I80 -> 11014.526 | H6: =H5*Assumptions!I81 -> 11967.912 | K6: Forecast = Revenue x OPM% from Assumptions
A7: Operating Margin % | B7: =B6/B5 -> 0.31351184 | C7: =C6/C5 -> 0.34768788 | D7: =D6/D5 -> 0.28909644 | F7: =F6/F5 -> 0.3 | G7: =G6/G5 -> 0.315 | H7: =H6/H5 -> 0.33
A9: DCAI - Data Center & AI | B9: =Segment_Revenue!B8 -> 15980 | C9: =Segment_Revenue!C8 -> 16125 | D9: =Segment_Revenue!D8 -> 16919 | F9: =Segment_Revenue!F8 -> 17920 | G9: =Segment_Revenue!G8 -> 21755 | H9: =Segment_Revenue!H8 -> 24987.5 | K9: Revenue <- links Segment_Revenue
A10: Operating Income | B10: 945 | C10: 1414 | D10: 3422 | F10: =F9*Assumptions!I83 -> 5017.6 | G10: =G9*Assumptions!I84 -> 6091.4 | H10: =H9*Assumptions!I85 -> 6746.625 | K10: Forecast = Revenue x OPM% from Assumptions
A11: Operating Margin % | B11: =B10/B9 -> 0.059136421 | C11: =C10/C9 -> 0.087689922 | D11: =D10/D9 -> 0.20225782 | F11: =F10/F9 -> 0.28 | G11: =G10/G9 -> 0.28 | H11: =H10/H9 -> 0.27
A13: Intel Foundry | B13: =Segment_Revenue!B11 -> 18504 | C13: =Segment_Revenue!C11 -> 17317 | D13: =Segment_Revenue!D11 -> 17826 | F13: =Segment_Revenue!F11 -> 18398.5 | G13: =Segment_Revenue!G11 -> 20109.3 | H13: =Segment_Revenue!H11 -> 22255.25 | K13: Revenue <- links Segment_Revenue
A14: Operating Income | B14: -7083 | C14: -13291 | D14: -10318 | F14: =F13*Assumptions!I87 -> -7727.37 | G14: =G13*Assumptions!I88 -> -6434.976 | H14: =H13*Assumptions!I89 -> -4896.155 | K14: Forecast = Revenue x OPM% from Assumptions
A15: Operating Margin % | B15: =B14/B13 -> -0.3827821 | C15: =C14/C13 -> -0.76751169 | D15: =D14/D13 -> -0.57881746 | F15: =F14/F13 -> -0.42 | G15: =G14/G13 -> -0.32 | H15: =H14/H13 -> -0.22
A17: All Other (Mobileye + IMS + Other) | B17: =Segment_Revenue!B14 -> 5463 | C17: =Segment_Revenue!C14 -> 3601 | D17: =Segment_Revenue!D14 -> 3563 | F17: =Segment_Revenue!F14 -> 3472 | G17: =Segment_Revenue!G14 -> 3780 | H17: =Segment_Revenue!H14 -> 4090 | K17: Revenue <- links Segment_Revenue
A18: Operating Income | B18: 1507 | C18: -57 | D18: 264 | F18: =F17*Assumptions!I91 -> 486.08 | G18: =G17*Assumptions!I92 -> 680.4 | H18: =H17*Assumptions!I93 -> 818 | K18: Forecast = Revenue x OPM% from Assumptions
A19: Operating Margin % | B19: =B18/B17 -> 0.27585576 | C19: =C18/C17 -> -0.015828936 | D19: =D18/D17 -> 0.074094864 | F19: =F18/F17 -> 0.14 | G19: =G18/G17 -> 0.18 | H19: =H18/H17 -> 0.2
A21: Corporate Unallocated | B21: -5199 | C21: -11177 | D21: -5518 | F21: =Assumptions!I156 -> -5000 | G21: =Assumptions!I157 -> -4500 | H21: =Assumptions!I158 -> -4000 | K21: From Assumptions. Declining from cost-cutting.
A22: Sum of Segment Operating Income + Corp Unalloc | B22: =B6+B10+B14+B18+B21 -> 298 | C22: =C6+C10+C14+C18+C21 -> -11517 | D22: =D6+D10+D14+D18+D21 -> -2833 | F22: =F6+F10+F14+F18+F21 -> 2604.31 | G22: =G6+G10+G14+G18+G21 -> 6851.3503 | H22: =H6+H10+H14+H18+H21 -> 10636.382 | K22: KEY OUTPUT. Links to Consolidated_PL EBIT.
A24: CROSS-CHECK: Sum Seg OI vs Consolidated EBIT
A25: Segment Sum OI | B25: =B22 -> 298 | C25: =C22 -> -11517 | D25: =D22 -> -2833 | F25: =F22 -> 2604.31 | G25: =G22 -> 6851.3503 | H25: =H22 -> 10636.382
A26: Consolidated_PL EBIT | B26: =Consolidated_PL!B17 -> 298 | C26: =Consolidated_PL!C17 -> -11517 | D26: =Consolidated_PL!D17 -> -2833 | F26: =Consolidated_PL!F17 -> 2604.31 | G26: =Consolidated_PL!G17 -> 6851.3503 | H26: =Consolidated_PL!H17 -> 10636.382 | K26: TODO: fill in pass 2 after Consolidated_PL built
A27: Difference (MUST = 0) | B27: =B25-B26 -> 0 | C27: =C25-C26 -> 0 | D27: =D25-D26 -> 0 | F27: =F25-F26 -> 0 | G27: =G25-G26 -> 0 | H27: =H25-H26 -> 0 | K27: MUST = 0 - validates segment/consolidated linkage
A29: DATA LEGEND
A30: Blue font: Historical hardcoded data
A31: Green font: Cross-sheet link
A32: Blue fill + dark font: Editable assumption
A33: Yellow fill: Key output row
A34: Black font: Formula / calculated cell
A35: Grey italic: Memo / percentage row
A37: DATA SOURCES
A38: - 2022-2025 10-Ks: Consolidated P&L, Balance Sheet, Cash Flow, Segment data
A39: - 2026 Q1 10-Q: Q1 2026 vs Q1 2025 segment + consolidated data
A40: - Q1 2026 Earnings Call (Apr 23, 2026): FY2026 management guidance
A41: - intc_assumptions.md: All forecast assumptions with scenario narratives
A42: - Bloomberg / Damodaran / FRED: WACC inputs (Rf, ERP, Beta) as of May 2026

Sheet Consolidated_PL
A1: Intel (INTC) - Consolidated Income Statement
A2: USD Million (except per-share data)
B3: 2023A | C3: 2024A | D3: 2025A | F3: 2026E | G3: 2027E | H3: 2028E | K3: Notes
A4: USD Million (except per-share data) | K4: Cost structure by type. EBIT = Segment_PL Sum OI (segment-driven).
A5: Net Revenue | B5: =Segment_Revenue!B21 -> 54228 | C5: =Segment_Revenue!C21 -> 53101 | D5: =Segment_Revenue!D21 -> 52853 | F5: =Segment_Revenue!F21 -> 54652 | G5: =Segment_Revenue!G21 -> 61801.75 | H5: =Segment_Revenue!H21 -> 67643.9 | K5: <- Segment_Revenue consolidated total
A6: Cost of Sales | B6: 32517 | C6: 35756 | D6: 34478 | F6: =F5*Assumptions!I96 -> 33610.98 | G6: =G5*Assumptions!I97 -> 36463.033 | H6: =H5*Assumptions!I98 -> 38218.803 | K6: Revenue x COGS% from Assumptions
A7: Gross Profit | B7: 21711 | C7: 17345 | D7: 18375 | F7: =F5-F6 -> 21041.02 | G7: =G5-G6 -> 25338.717 | H7: =H5-H6 -> 29425.096 | K7: Revenue - COGS
A8: Gross Margin % | B8: =B7/B5 -> 0.40036513 | C8: =C7/C5 -> 0.32664168 | D8: =D7/D5 -> 0.34766238 | F8: =F7/F5 -> 0.385 | G8: =G7/G5 -> 0.41 | H8: =H7/H5 -> 0.435
A10: Operating Expenses (by cost type)
A11: Research & Development | B11: 16046 | C11: 16546 | D11: 13774 | F11: =F5*Assumptions!I100 -> 14209.52 | G11: =G5*Assumptions!I101 -> 15450.438 | H11: =H5*Assumptions!I102 -> 16234.536 | K11: Revenue x R&D%
A12: Marketing, General & Administrative | B12: 5634 | C12: 5507 | D12: 4624 | F12: =F5*Assumptions!I104 -> 4372.16 | G12: =G5*Assumptions!I105 -> 4635.1312 | H12: =H5*Assumptions!I106 -> 4735.073 | K12: Revenue x MG&A%
A13: Restructuring & Other Charges | B13: -62 | C13: 6970 | D13: 2191 | F13: =Assumptions!I114 -> 500 | G13: =Assumptions!I114 -> 500 | H13: =Assumptions!I114 -> 500 | K13: From Assumptions; winding down
A14: Total OpEx (per cost rates) | B14: =B11+B12+B13 -> 21618 | C14: =C11+C12+C13 -> 29023 | D14: =D11+D12+D13 -> 20589 | F14: =F11+F12+F13 -> 19081.68 | G14: =G11+G12+G13 -> 20585.569 | H14: =H11+H12+H13 -> 21469.609 | K14: R&D + MG&A + Restructuring (top-down cost build)
A16: EBIT - Segment-Driven
A17: EBIT (Operating Income) | B17: =Segment_PL!B22 -> 298 | C17: =Segment_PL!C22 -> -11517 | D17: =Segment_PL!D22 -> -2833 | F17: =Segment_PL!F22 -> 2604.31 | G17: =Segment_PL!G22 -> 6851.3503 | H17: =Segment_PL!H22 -> 10636.382 | K17: <- Segment_PL Sum of Segment OI. SEGMENT-DRIVEN source of truth.
A18: EBIT Margin % | B18: =B17/B5 -> 0.0054953161 | C18: =C17/C5 -> -0.21688857 | D18: =D17/D5 -> -0.053601498 | F18: =F17/F5 -> 0.047652602 | G18: =G17/G5 -> 0.11086013 | H18: =H17/H5 -> 0.15724082
A19: Implied Total OpEx (GP - EBIT) | B19: =B7-B17 -> 21413 | C19: =C7-C17 -> 28862 | D19: =D7-D17 -> 21208 | F19: =F7-F17 -> 18436.71 | G19: =G7-G17 -> 18487.367 | H19: =H7-H17 -> 18788.714 | K19: Transparency: GP - EBIT. May differ from top-down OpEx above.
A21: Non-Operating Items
A22: Interest & Other, Net | B22: 629 | C22: 226 | D22: 3257 | F22: =Assumptions!I147 -> -800 | G22: =Assumptions!I148 -> -600 | H22: =Assumptions!I149 -> -400 | K22: Net interest expense on debt
A23: Gains/Losses on Equity Investments | B23: 40 | C23: 242 | D23: 514 | F23: 0 | G23: 0 | H23: 0 | K23: Unpredictable; set to 0 for forecast
A24: Income (Loss) Before Taxes | B24: =B17+B22+B23 -> 967 | C24: =C17+C22+C23 -> -11049 | D24: =D17+D22+D23 -> 938 | F24: =F17+F22+F23 -> 1804.31 | G24: =G17+G22+G23 -> 6251.3503 | H24: =H17+H22+H23 -> 10236.382 | K24: EBIT + Interest + Equity Gains
A25: Provision for (Benefit from) Taxes | B25: -913 | C25: 8023 | D25: 1531 | F25: =IF(F24>0,F24*Assumptions!I143,0) -> 216.5172 | G25: =IF(G24>0,G24*Assumptions!I144,0) -> 812.67553 | H25: =IF(H24>0,H24*Assumptions!I145,0) -> 1330.7297 | K25: Tax on positive pretax only (valuation allowance shields US losses)
A26: Net Income (Loss) | B26: =B24-B25 -> 1880 | C26: =C24-C25 -> -19072 | D26: =D24-D25 -> -593 | F26: =F24-F25 -> 1587.7928 | G26: =G24-G25 -> 5438.6747 | H26: =H24-H25 -> 8905.6523 | K26: Pretax - Tax
A27: Net Income Margin % | B27: =B26/B5 -> 0.034668437 | C27: =C26/C5 -> -0.35916461 | D27: =D26/D5 -> -0.011219798 | F27: =F26/F5 -> 0.029052785 | G27: =G26/G5 -> 0.088001953 | H27: =H26/H5 -> 0.13165492
A28: Less: Net Income Attributable to NCI | B28: -14 | C28: -477 | D28: 293 | F28: =Assumptions!I151 -> 750 | G28: =Assumptions!I152 -> 1100 | H28: =Assumptions!I153 -> 1100 | K28: NCI from Assumptions (AZ SCIP + Mobileye; Ireland SCIP eliminated Apr 2026)
A29: Net Income Attributable to Intel | B29: =B26-B28 -> 1894 | C29: =C26-C28 -> -18595 | D29: =D26-D28 -> -886 | F29: =F26-F28 -> 837.7928 | G29: =G26-G28 -> 4338.6747 | H29: =H26-H28 -> 7805.6523 | K29: NI - NCI. Key EPS driver.
A31: Memo Items
A32: D&A (Memo) | B32: 7847 | C32: 9951 | D32: 10757 | F32: =Assumptions!I109 -> 12500 | G32: =Assumptions!I110 -> 13200 | H32: =Assumptions!I111 -> 13800 | K32: Reference for EBITDA calc
A33: SBC (Memo) | B33: 3229 | C33: 3410 | D33: 2434 | F33: =Assumptions!I113 -> 2500 | G33: =Assumptions!I113 -> 2500 | H33: =Assumptions!I113 -> 2500 | K33: Reference for CFO/FCF bridge
A34: Diluted Shares Outstanding (M) | B34: 4212 | C34: 4280 | D34: 4530 | F34: =Assumptions!I135 -> 5100 | G34: =Assumptions!I136 -> 5180 | H34: =Assumptions!I137 -> 5250 | K34: Basic shares from Assumptions; diluted approximates basic
A35: Diluted EPS ($) | B35: =B29/B34 -> 0.44966762 | C35: =C29/C34 -> -4.3446262 | D35: =D29/D34 -> -0.19558499 | F35: =F29/F34 -> 0.1642731 | G35: =G29/G34 -> 0.83758199 | H35: =H29/H34 -> 1.4867909 | K35: NI to Intel / Shares. KEY OUTPUT
A36: Dividends per Share (Memo) | B36: 0.74 | C36: 0.38 | D36: 0 | F36: =Assumptions!I139 -> 0 | G36: =Assumptions!I139 -> 0 | H36: =Assumptions!I139 -> 0 | K36: Suspended; no reinstatement expected
A38: DATA LEGEND
A39: Blue font: Historical hardcoded data
A40: Green font: Cross-sheet link
A41: Blue fill + dark font: Editable assumption
A42: Yellow fill: Key output row
A43: Black font: Formula / calculated cell
A44: Grey italic: Memo / percentage row
A46: DATA SOURCES
...

Sheet BS
A1: Intel (INTC) - Balance Sheet
A2: USD Million (except per-share data)
B3: 2023A | C3: 2024A | D3: 2025A | F3: 2026E | G3: 2027E | H3: 2028E | K3: Notes
A4: USD Million | K4: Cash = Total L&E - Non-Cash Assets (plug). Balance check row must = 0.
A5: ASSETS
A6: Current Assets
A7: Cash and Cash Equivalents (PLUG) | B7: 7079 | C7: 8249 | D7: 14265 | F7: =F43-F20-(F8+F9+F10+F11) -> 21388.263 | G7: =G43-G20-(G8+G9+G10+G11) -> 21900.335 | H7: =H43-H20-(H8+H9+H10+H11) -> 25995.591 | K7: PLUG: = Total L&E - all non-cash assets. Ensures A = L+E.
A8: Short-term Investments (Marketable Securities) | B8: 17955 | C8: 13813 | D8: 23151 | F8: 24000 | G8: 24000 | H8: 24000 | K8: TODO: Model as % of total cash or flat. Current: flat ~$24B assumption.
A9: Accounts Receivable, Net | B9: 3402 | C9: 3478 | D9: 3839 | F9: =Consolidated_PL!F5*Assumptions!I117/365 -> 3743.2877 | G9: =Consolidated_PL!G5*Assumptions!I117/365 -> 4232.9966 | H9: =Consolidated_PL!H5*Assumptions!I117/365 -> 4633.1438 | K9: Revenue x AR Days / 365
A10: Inventories | B10: 11127 | C10: 12198 | D10: 11618 | F10: =Consolidated_PL!F6*Assumptions!I119/365 -> 11510.61 | G10: =Consolidated_PL!G6*Assumptions!I119/365 -> 12487.34 | H10: =Consolidated_PL!H6*Assumptions!I119/365 -> 13088.631 | K10: COGS x Inventory Days / 365
A11: Other Current Assets | B11: 3706 | C11: 9586 | D11: 10815 | F11: =Consolidated_PL!F5*Assumptions!I121 -> 8197.8 | G11: =Consolidated_PL!G5*Assumptions!I121 -> 9270.2625 | H11: =Consolidated_PL!H5*Assumptions!I121 -> 10146.585 | K11: Revenue x Other CA% (incl. refundable tax credits)
A12: Total Current Assets | B12: =B7+B8+B9+B10+B11 -> 43269 | C12: =C7+C8+C9+C10+C11 -> 47324 | D12: =D7+D8+D9+D10+D11 -> 63688 | F12: =F7+F8+F9+F10+F11 -> 68839.96 | G12: =G7+G8+G9+G10+G11 -> 71890.934 | H12: =H7+H8+H9+H10+H11 -> 77863.951 | K12: Cash + Securities + AR + Inventory + Other CA
A14: Non-Current Assets
A15: Property, Plant & Equipment, Net | B15: 96647 | C15: 107919 | D15: 105414 | F15: =D15+Assumptions!I126-Consolidated_PL!F32 -> 110614 | G15: =F15+Assumptions!I127-Consolidated_PL!G32 -> 116914 | H15: =G15+Assumptions!I128-Consolidated_PL!H32 -> 124114 | K15: Prior PP&E + Gross CapEx - D&A. Govt incentives not explicitly modelled (reducing gross PP&E).
A16: Equity Investments | B16: 5829 | C16: 5383 | D16: 8512 | F16: 8500 | G16: 8500 | H16: 8500 | K16: Includes Altera 49% retained stake (equity method). Flat forecast.
A17: Goodwill | B17: 27591 | C17: 24693 | D17: 23912 | F17: 20012 | G17: 20012 | H17: 20012 | K17: Post-Q1 2026 $3.9B Mobileye impairment. Approx $20012M.
A18: Identified Intangible Assets, Net | B18: 4589 | C18: 3691 | D18: 2772 | F18: =D18-500 -> 2272 | G18: =F18-500 -> 1772 | H18: =G18-500 -> 1272 | K18: Amortising ~$500M/year
A19: Other Long-Term Assets | B19: 13647 | C19: 7475 | D19: 7131 | F19: 7000 | G19: 7000 | H19: 7000 | K19: Flat ~$7B assumption
A20: Total Non-Current Assets | B20: =B15+B16+B17+B18+B19 -> 148303 | C20: =C15+C16+C17+C18+C19 -> 149161 | D20: =D15+D16+D17+D18+D19 -> 147741 | F20: =F15+F16+F17+F18+F19 -> 148398 | G20: =G15+G16+G17+G18+G19 -> 154198 | H20: =H15+H16+H17+H18+H19 -> 160898
A21: TOTAL ASSETS | B21: =B12+B20 -> 191572 | C21: =C12+C20 -> 196485 | D21: =D12+D20 -> 211429 | F21: =F12+F20 -> 217237.96 | G21: =G12+G20 -> 226088.93 | H21: =H12+H20 -> 238761.95
A24: LIABILITIES & EQUITY
A25: Current Liabilities
A26: Accounts Payable | B26: 8578 | C26: 12556 | D26: 9882 | F26: =Consolidated_PL!F6*Assumptions!I118/365 -> 9208.4877 | G26: =Consolidated_PL!G6*Assumptions!I118/365 -> 9989.8719 | H26: =Consolidated_PL!H6*Assumptions!I118/365 -> 10470.905 | K26: COGS x AP Days / 365
A27: Accrued Compensation and Benefits | B27: 3655 | C27: 3343 | D27: 3990 | F27: =Consolidated_PL!F5*Assumptions!I120 -> 3825.64 | G27: =Consolidated_PL!G5*Assumptions!I120 -> 4326.1225 | H27: =Consolidated_PL!H5*Assumptions!I120 -> 4735.073 | K27: Revenue x Accrued Comp%
A28: Short-Term Debt | B28: 2288 | C28: 3729 | D28: 2499 | F28: 2500 | G28: 2500 | H28: 2500 | K28: Stable ~$2.5B assumption; commercial paper + current maturities
A29: Income Taxes Payable | B29: 1107 | C29: 1756 | D29: 604 | F29: =Consolidated_PL!F5*Assumptions!I123 -> 1093.04 | G29: =Consolidated_PL!G5*Assumptions!I123 -> 1236.035 | H29: =Consolidated_PL!H5*Assumptions!I123 -> 1352.878 | K29: Revenue x Tax Payable%
A30: Other Accrued Liabilities | B30: 12425 | C30: 14282 | D30: 14600 | F30: =Consolidated_PL!F5*Assumptions!I122 -> 13663 | G30: =Consolidated_PL!G5*Assumptions!I122 -> 15450.438 | H30: =Consolidated_PL!H5*Assumptions!I122 -> 16910.975 | K30: Revenue x Other CL%
A31: Total Current Liabilities | B31: =B26+B27+B28+B29+B30 -> 28053 | C31: =C26+C27+C28+C29+C30 -> 35666 | D31: =D26+D27+D28+D29+D30 -> 31575 | F31: =F26+F27+F28+F29+F30 -> 30290.168 | G31: =G26+G27+G28+G29+G30 -> 33502.467 | H31: =H26+H27+H28+H29+H30 -> 35969.831
A33: Non-Current Liabilities
A34: Long-Term Debt | B34: 46978 | C34: 46282 | D34: 44086 | F34: =Assumptions!I131-F28 -> 47000 | G34: =Assumptions!I132-G28 -> 44700 | H34: =Assumptions!I133-H28 -> 43500 | K34: Total Debt - ST Debt (from Assumptions)
A35: Other Long-Term Liabilities | B35: 6576 | C35: 9505 | D35: 9408 | F35: 9500 | G35: 9500 | H35: 9500 | K35: Flat ~$9.5B assumption. Includes tax, operating lease, other.
A36: Total Non-Current Liabilities | B36: =B34+B35 -> 53554 | C36: =C34+C35 -> 55787 | D36: =D34+D35 -> 53494 | F36: =F34+F35 -> 56500 | G36: =G34+G35 -> 54200 | H36: =H34+H35 -> 53000
A37: TOTAL LIABILITIES | B37: =B31+B36 -> 81607 | C37: =C31+C36 -> 91453 | D37: =D31+D36 -> 85069 | F37: =F31+F36 -> 86790.168 | G37: =G31+G36 -> 87702.467 | H37: =H31+H36 -> 88969.831
A39: Stockholders' Equity
A40: Total Intel Stockholders' Equity | B40: 105590 | C40: 99270 | D40: 114281 | F40: =D40+Consolidated_PL!F29+Consolidated_PL!F33+Assumptions!I140 -> 117918.79 | G40: =F40+Consolidated_PL!G29+Consolidated_PL!G33+Assumptions!I140 -> 125057.47 | H40: =G40+Consolidated_PL!H29+Consolidated_PL!H33+Assumptions!I140 -> 135663.12 | K40: Prior Equity + NI to Intel + SBC + Net Equity Issuance. Dividends = 0.
A41: Non-Controlling Interests | B41: 4375 | C41: 5762 | D41: 12079 | F41: =D41+Consolidated_PL!F28-300 -> 12529 | G41: =F41+Consolidated_PL!G28-300 -> 13329 | H41: =G41+Consolidated_PL!H28-300 -> 14129 | K41: Prior NCI + P&L NCI - estimated distributions (~$300M). AZ SCIP + Mobileye remain.
A42: Total Stockholders' Equity | B42: =B40+B41 -> 109965 | C42: =C40+C41 -> 105032 | D42: =D40+D41 -> 126360 | F42: =F40+F41 -> 130447.79 | G42: =G40+G41 -> 138386.47 | H42: =H40+H41 -> 149792.12
A43: TOTAL LIABILITIES & EQUITY | B43: =B37+B42 -> 191572 | C43: =C37+C42 -> 196485 | D43: =D37+D42 -> 211429 | F43: =F37+F42 -> 217237.96 | G43: =G37+G42 -> 226088.93 | H43: =H37+H42 -> 238761.95
A45: Total Assets | B45: =B12+B20 -> 191572 | C45: =C12+C20 -> 196485 | D45: =D12+D20 -> 211429 | F45: =F12+F20 -> 217237.96 | G45: =G12+G20 -> 226088.93 | H45: =H12+H20 -> 238761.95
A46: Total L&E (from above) | B46: =B43 -> 191572 | C46: =C43 -> 196485 | D46: =D43 -> 211429 | F46: =F43 -> 217237.96 | G46: =G43 -> 226088.93 | H46: =H43 -> 238761.95
...

Sheet Cash_Flow
A1: Intel (INTC) - Cash Flow Statement
A2: USD Million (except per-share data)
B3: 2023A | C3: 2024A | D3: 2025A | F3: 2026E | G3: 2027E | H3: 2028E | K3: Notes
A4: USD Million | K4: WC changes linked to BS deltas. CFO + CFI = FCF.
A5: Operating Activities
A6: Net Income (Loss) | B6: =Consolidated_PL!B26 -> 1880 | C6: =Consolidated_PL!C26 -> -19072 | D6: =Consolidated_PL!D26 -> -593 | F6: =Consolidated_PL!F26 -> 1587.7928 | G6: =Consolidated_PL!G26 -> 5438.6747 | H6: =Consolidated_PL!H26 -> 8905.6523 | K6: <- Consolidated_PL
A7: (+) Depreciation & Amortization | B7: =Consolidated_PL!B32 -> 7847 | C7: =Consolidated_PL!C32 -> 9951 | D7: =Consolidated_PL!D32 -> 10757 | F7: =Consolidated_PL!F32 -> 12500 | G7: =Consolidated_PL!G32 -> 13200 | H7: =Consolidated_PL!H32 -> 13800
A8: (+) Share-Based Compensation | B8: =Consolidated_PL!B33 -> 3229 | C8: =Consolidated_PL!C33 -> 3410 | D8: =Consolidated_PL!D33 -> 2434 | F8: =Consolidated_PL!F33 -> 2500 | G8: =Consolidated_PL!G33 -> 2500 | H8: =Consolidated_PL!H33 -> 2500
A9: Deferred Taxes | B9: -2033 | C9: 6132 | D9: 328 | F9: 0 | G9: 0 | H9: 0 | K9: TODO: Model deferred tax. Set to 0 for now (valuation allowance limits).
A10: Other Non-Cash / Non-Recurring | B10: 6871 | C10: 11925 | D10: -2958 | F10: 0 | G10: 0 | H10: 0 | K10: Restructuring charges, impairments, gains/losses, etc. Set to 0 for forecast.
A12: Working Capital Changes
A13: Change in AR (-increase = outflow) | C13: =-(BS!C9-BS!B9) -> -76 | D13: =-(BS!D9-BS!C9) -> -361 | F13: =-(BS!F9-BS!D9) -> 95.712329 | G13: =-(BS!G9-BS!F9) -> -489.7089 | H13: =-(BS!H9-BS!G9) -> -400.14726 | K13: Links to BS bs_ar
A14: Change in Inventory (-increase = outflow) | C14: =-(BS!C10-BS!B10) -> -1071 | D14: =-(BS!D10-BS!C10) -> 580 | F14: =-(BS!F10-BS!D10) -> 107.39041 | G14: =-(BS!G10-BS!F10) -> -976.73031 | H14: =-(BS!H10-BS!G10) -> -601.29144 | K14: Links to BS bs_inventory
A15: Change in Other CA (-increase = outflow) | C15: =-(BS!C11-BS!B11) -> -5880 | D15: =-(BS!D11-BS!C11) -> -1229 | F15: =-(BS!F11-BS!D11) -> 2617.2 | G15: =-(BS!G11-BS!F11) -> -1072.4625 | H15: =-(BS!H11-BS!G11) -> -876.3225 | K15: Links to BS bs_other_ca
A16: Change in AP (+increase = inflow) | C16: =BS!C26-BS!B26 -> 3978 | D16: =BS!D26-BS!C26 -> -2674 | F16: =BS!F26-BS!D26 -> -673.51233 | G16: =BS!G26-BS!F26 -> 781.38425 | H16: =BS!H26-BS!G26 -> 481.03315 | K16: Links to BS bs_ap
A17: Change in Accrued Comp (+increase = inflow) | C17: =BS!C27-BS!B27 -> -312 | D17: =BS!D27-BS!C27 -> 647 | F17: =BS!F27-BS!D27 -> -164.36 | G17: =BS!G27-BS!F27 -> 500.4825 | H17: =BS!H27-BS!G27 -> 408.9505 | K17: Links to BS bs_accrued_comp
A18: Change in Other CL (+increase = inflow) | C18: =BS!C30-BS!B30 -> 1857 | D18: =BS!D30-BS!C30 -> 318 | F18: =BS!F30-BS!D30 -> -937 | G18: =BS!G30-BS!F30 -> 1787.4375 | H18: =BS!H30-BS!G30 -> 1460.5375 | K18: Links to BS bs_other_cl
A19: Change in Tax Payable (+increase = inflow) | C19: =BS!C29-BS!B29 -> 649 | D19: =BS!D29-BS!C29 -> -1152 | F19: =BS!F29-BS!D29 -> 489.04 | G19: =BS!G29-BS!F29 -> 142.995 | H19: =BS!H29-BS!G29 -> 116.843 | K19: Links to BS bs_tax_payable
A21: Net Cash from Operating Activities (CFO) | B21: =B6+B7+B8+B17+B18+B13+B14+B15+B16+B17+B18+B19 -> 12956 | C21: =C6+C7+C8+C17+C18+C13+C14+C15+C16+C17+C18+C19 -> -5021 | D21: =D6+D7+D8+D17+D18+D13+D14+D15+D16+D17+D18+D19 -> 9692 | F21: =F6+F7+F8+F17+F18+F13+F14+F15+F16+F17+F18+F19 -> 17020.903 | G21: =G6+G7+G8+G17+G18+G13+G14+G15+G16+G17+G18+G19 -> 24099.992 | H21: =H6+H7+H8+H17+H18+H13+H14+H15+H16+H17+H18+H19 -> 27664.743 | K21: NI + D&A + SBC + DeferredTax + OtherNonCash + Sum(WC Changes)
A23: Investing Activities
A24: Capital Expenditure (Gross CapEx) | B24: -25750 | C24: -25122 | D24: -17672 | F24: =-Assumptions!I126 -> -17700 | G24: =-Assumptions!I127 -> -19500 | H24: =-Assumptions!I128 -> -21000 | K24: Gross CapEx (negative). From Assumptions.
A25: CapEx / Revenue % | B25: =-B24/Consolidated_PL!B5 -> 0.47484694 | C25: =-C24/Consolidated_PL!C5 -> 0.47309844 | D25: =-D24/Consolidated_PL!D5 -> 0.33436134 | F25: =-F24/Consolidated_PL!F5 -> 0.32386738 | G25: =-G24/Consolidated_PL!G5 -> 0.31552505 | H25: =-H24/Consolidated_PL!H5 -> 0.31044928
A26: Other Investing Activities, Net | B26: 1546 | C26: 1581 | D26: -1175 | F26: 0 | G26: 0 | H26: 0 | K26: Govt incentives, divestitures, ST investment net. Set to 0 for forecast.
A27: Net Cash from Investing Activities (CFI) | B27: =B24+B26 -> -24204 | C27: =C24+C26 -> -23541 | D27: =D24+D26 -> -18847 | F27: =F24+F26 -> -17700 | G27: =G24+G26 -> -19500 | H27: =H24+H26 -> -21000
A28: Free Cash Flow (FCF = CFO + CFI) | B28: =B21+B27 -> -11248 | C28: =C21+C27 -> -28562 | D28: =D21+D27 -> -9155 | F28: =F21+F27 -> -679.09679 | G28: =G21+G27 -> 4599.9923 | H28: =H21+H27 -> 6664.7433 | K28: CFO + CFI. KEY OUTPUT.
A29: FCF / Revenue % | B29: =B28/Consolidated_PL!B5 -> -0.20742052 | C29: =C28/Consolidated_PL!C5 -> -0.53788064 | D29: =D28/Consolidated_PL!D5 -> -0.17321628 | F29: =F28/Consolidated_PL!F5 -> -0.012425836 | G29: =G28/Consolidated_PL!G5 -> 0.074431424 | H29: =H28/Consolidated_PL!H5 -> 0.098526893
A31: Financing Activities
A32: Net Change in Debt | B32: 11453 | C32: -462 | D32: -2757 | F32: =Assumptions!I131-(BS!D34+BS!D28) -> 2915 | G32: =Assumptions!I132-Assumptions!I131 -> -2300 | H32: =Assumptions!I133-Assumptions!I132 -> -1200 | K32: Change in Total Debt from Assumptions
A33: Net Equity Issuance / (Repurchase) | B33: 2567 | C33: 356 | D33: 18586 | F33: =Assumptions!I140 -> 300 | G33: =Assumptions!I140 -> 300 | H33: =Assumptions!I140 -> 300 | K33: ESPP proceeds net of RSU withholdings. FY2025 inflated by strategic placements.
A34: Dividends Paid | B34: -3088 | C34: -1599 | D34: 0 | F34: =-Assumptions!I139*Assumptions!I135 -> 0 | G34: =-Assumptions!I139*Assumptions!I135 -> 0 | H34: =-Assumptions!I139*Assumptions!I135 -> 0 | K34: Dividends suspended; = 0.
A35: Partner Contributions (SCIP) & Other Financing | B35: 3696 | C35: 12471 | D35: 1827 | F35: 500 | G35: 500 | H35: 500 | K35: AZ SCIP ongoing partner contributions. Ireland SCIP eliminated Apr 2026.
A36: Net Cash from Financing Activities (CFF) | B36: =B32+B33+B34+B35 -> 14628 | C36: =C32+C33+C34+C35 -> 10766 | D36: =D32+D33+D34+D35 -> 17656 | F36: =F32+F33+F34+F35 -> 3715 | G36: =G32+G33+G34+G35 -> -1500 | H36: =H32+H33+H34+H35 -> -400
A37: Net Increase (Decrease) in Cash | B37: =B21+B27+B36 -> 3380 | C37: =C21+C27+C36 -> -17796 | D37: =D21+D27+D36 -> 8501 | F37: =F21+F27+F36 -> 3035.9032 | G37: =G21+G27+G36 -> 3099.9923 | H37: =H21+H27+H36 -> 6264.7433 | K37: CFO + CFI + CFF
A39: DATA LEGEND
A40: Blue font: Historical hardcoded data
A41: Green font: Cross-sheet link
A42: Blue fill + dark font: Editable assumption
A43: Yellow fill: Key output row
A44: Black font: Formula / calculated cell
A45: Grey italic: Memo / percentage row
...

Sheet DCF
A1: Intel (INTC) - Discounted Cash Flow Valuation
A2: USD Million (except per-share data & multiples)
F3: Year 1 | G3: Year 2 | H3: Year 3
A4: Forecast Period | K4: DCF based on Unlevered Free Cash Flow (UFCF). TV = Gordon Growth Model.
A5: EBIT | B5: =Consolidated_PL!B17 -> 298 | C5: =Consolidated_PL!C17 -> -11517 | D5: =Consolidated_PL!D17 -> -2833 | F5: =Consolidated_PL!F17 -> 2604.31 | G5: =Consolidated_PL!G17 -> 6851.3503 | H5: =Consolidated_PL!H17 -> 10636.382 | K5: <- Consolidated_PL (segment-driven)
A6: (-) Tax on EBIT | B6: 0 | C6: 0 | D6: 0 | F6: =F5*Assumptions!I143 -> 312.5172 | G6: =G5*Assumptions!I144 -> 890.67553 | H6: =H5*Assumptions!I145 -> 1382.7297 | K6: EBIT x ETR from Assumptions
A7: NOPAT (= EBIT - Tax on EBIT) | B7: =B5-B6 -> 298 | C7: =C5-C6 -> -11517 | D7: =D5-D6 -> -2833 | F7: =F5-F6 -> 2291.7928 | G7: =G5-G6 -> 5960.6747 | H7: =H5-H6 -> 9253.6523 | K7: Net Operating Profit After Tax
A8: (+) D&A | B8: =Consolidated_PL!B32 -> 7847 | C8: =Consolidated_PL!C32 -> 9951 | D8: =Consolidated_PL!D32 -> 10757 | F8: =Consolidated_PL!F32 -> 12500 | G8: =Consolidated_PL!G32 -> 13200 | H8: =Consolidated_PL!H32 -> 13800
A9: (-) Capital Expenditure | B9: 0 | C9: 0 | D9: 0 | F9: =-Assumptions!I126 -> -17700 | G9: =-Assumptions!I127 -> -19500 | H9: =-Assumptions!I128 -> -21000 | K9: Gross CapEx (negative). From Assumptions.
A10: (-) Change in Net Working Capital | B10: 0 | C10: 0 | D10: 0 | F10: =-(Consolidated_PL!F5-Consolidated_PL!D5)*0.1 -> -179.9 | G10: =-(Consolidated_PL!G5-Consolidated_PL!F5)*0.1 -> -714.975 | H10: =-(Consolidated_PL!H5-Consolidated_PL!G5)*0.1 -> -584.215 | K10: ≈ 10% of ΔRevenue (AR 7% + Inv 21% - AP 17% ≈ 11%). Sign: NWC increase = cash outflow.
A11: Unlevered Free Cash Flow (UFCF) | B11: =B7+B8+B9+B10 -> 8145 | C11: =C7+C8+C9+C10 -> -1566 | D11: =D7+D8+D9+D10 -> 7924 | F11: =F7+F8+F9+F10 -> -3088.1072 | G11: =G7+G8+G9+G10 -> -1054.3003 | H11: =H7+H8+H9+H10 -> 1469.4373 | K11: NOPAT + D&A + CapEx (neg) + ΔNWC (neg if outflow)
A12: Discount Factor | F12: =1/(1+Assumptions!I18)^1 -> 0.90364848 | G12: =1/(1+Assumptions!I18)^2 -> 0.81658058 | H12: =1/(1+Assumptions!I18)^3 -> 0.7379018 | K12: 1/(1+WACC)^t. WACC from Assumptions (~10.5-10.7%)
A13: PV of UFCF | F13: =F11*F12 -> -2790.5634 | G13: =G11*G12 -> -860.92113 | H13: =H11*H12 -> 1084.3005 | K13: UFCF x Discount Factor
A15: Terminal Value (Gordon Growth Model)
A16: Terminal Year UFCF (FY2028E) | H16: =H11 -> 1469.4373 | K16: UFCF in final explicit forecast year
A17: Terminal Growth Rate (g) | H17: =Assumptions!I13 -> 0.025 | K17: From Assumptions. Base = 2.5%.
A18: Terminal Value (TV = UFCF x (1+g) / (WACC-g)) | H18: =H11*(1+H17)/(Assumptions!I18-H17) -> 18452.353 | K18: Gordon Growth: TV = UFCF_terminal x (1+g) / (WACC - g)
A19: PV of Terminal Value | H19: =H18*H12 -> 13616.024 | K19: TV x Discount Factor of final year
A21: Enterprise Value Bridge
A22: Sum of PV of UFCFs (FY2026E-FY2028E) | H22: =F13+G13+H13 -> -2567.1841 | K22: Sum of PV of UFCF for explicit forecast period
A23: (+) PV of Terminal Value | H23: =H19 -> 13616.024
A24: Enterprise Value (EV) | H24: =H22+H23 -> 11048.84 | K24: Sum PV UFCF + PV TV
A25: TV as % of EV | H25: =H18/H24 -> 1.6700715
A27: Equity Value Bridge
A28: Enterprise Value | H28: =H24 -> 11048.84
A29: (+) Cash & Equivalents | H29: =BS!H7 -> 25995.591 | K29: <- BS Cash (latest forecast year)
A30: (+) Marketable Securities | H30: =BS!H8 -> 24000 | K30: <- BS Short-term Investments
A31: (-) Total Debt | H31: =BS!H34+BS!H28 -> 46000 | K31: <- BS LT Debt + ST Debt
A32: (-) Non-Controlling Interests | H32: =BS!H41 -> 14129 | K32: <- BS NCI
A33: Equity Value | H33: =H28+H29+H30-H31-H32 -> 915.43078 | K33: EV + Cash + Securities - Debt - NCI. KEY OUTPUT.
A34: Diluted Shares Outstanding (M) | H34: =Consolidated_PL!H34 -> 5250 | K34: <- Consolidated_PL. FY2028E diluted shares.
A35: Implied Share Price ($) | H35: =H33/H34 -> 0.17436777 | K35: Equity Value / Shares. CENTRAL OUTPUT OF THE MODEL.
A37: DCF Summary
A38: WACC | H38: =Assumptions!I18 -> 0.106625
A39: Terminal Growth Rate | H39: =Assumptions!I13 -> 0.025
A40: Sum PV UFCF | H40: =H22 -> -2567.1841
A41: PV Terminal Value | H41: =H23 -> 13616.024
A42: TV % of EV | H42: =H23/H24 -> 1.2323487
A43: Enterprise Value | H43: =H24 -> 11048.84
A44: (+) Cash + Securities | H44: =H29+H30 -> 49995.591
...

Sheet Sensitivity
A1: Intel (INTC) - Sensitivity Analysis
A2: Implied Share Price ($) — WACC vs Terminal Growth Rate
A4: Base case WACC = 10.7%, Base case g = 2.5%
A6: Terminal g \ WACC | B6: 8 | C6: 9 | D6: 10 | E6: 10.7 | F6: 11 | G6: 12 | H6: 13
A7: 1.5% | K7: TODO: Implement 2D DATA TABLE in Excel. Open in Excel, select the table range, Data > What-If Analysis > Data Table. Row input: WACC cell (Assumptions!I{wacc_row}). Column input: g cell (Assumptions!I{tg_row}). Base case (WACC=10.7%, g=2.5%) is marked.
A8: 2.0%
A9: 2.5%
A10: 3.0%
A11: 3.5%
A13: Instructions
A14: 1. Open Intel_IB_Model.xlsx in Microsoft Excel
A15: 2. Go to Sensitivity tab
A16: 3. Select the table range (B7:H11)
A17: 4. Data > What-If Analysis > Data Table
A18: 5. Row input cell: =Assumptions!$I$18
A19: 6. Column input cell: =Assumptions!$I$13
A20: 7. Click OK. Table will populate with implied prices.

Sheet Ratio_Analysis
A1: Intel (INTC) - Ratio Analysis & Financial Metrics
A2: USD Million (except per-share data)
B3: 2023A | C3: 2024A | D3: 2025A | F3: 2026E | G3: 2027E | H3: 2028E | K3: Notes
